*** Starting uWSGI 2.0.21 (64bit) on [Tue Apr 25 18:14:10 2023] ***
compiled with version: 9.4.0 on 22 April 2023 10:04:56
os: Linux-5.15.0-1030-gcp #37~20.04.1-Ubuntu SMP Mon Feb 20 04:30:57 UTC 2023
nodename: teamwork-vm
machine: x86_64
clock source: unix
detected number of CPU cores: 2
current working directory: /home/eng/teamwork-ai
detected binary path: /usr/local/bin/uwsgi
!!! no internal routing support, rebuild with pcre support !!!
*** WARNING: you are running uWSGI without its master process manager ***
your processes number limit is 15648
your memory page size is 4096 bytes
detected max file descriptor number: 1024
lock engine: pthread robust mutexes
thunder lock: disabled (you can enable it with --thunder-lock)
uwsgi socket 0 bound to TCP address :3000 fd 3
Python version: 3.8.10 (default, Mar 13 2023, 10:26:41)  [GCC 9.4.0]
*** Python threads support is disabled. You can enable it with --enable-threads ***
Python main interpreter initialized at 0x55ad4944ffd0
your server socket listen backlog is limited to 100 connections
your mercy for graceful operations on workers is 60 seconds
mapped 72904 bytes (71 KB) for 1 cores
*** Operational MODE: single process ***
WSGI app 0 (mountpoint='') ready in 5 seconds on interpreter 0x55ad4944ffd0 pid: 52446 (default app)
*** uWSGI is running in multiple interpreter mode ***
spawned uWSGI worker 1 (and the only) (pid: 52446, cores: 1)
[pid: 52446|app: 0|req: 1/1] 147.92.150.194 () {38 vars in 556 bytes} [Tue Apr 25 18:14:43 2023] POST /callback => generated 2 bytes in 1 msecs (HTTP/1.1 200) 2 headers in 78 bytes (1 switches on core 0)
[pid: 52446|app: 0|req: 2/2] 147.92.150.193 () {38 vars in 558 bytes} [Tue Apr 25 18:14:53 2023] POST /callback => generated 2 bytes in 1 msecs (HTTP/1.1 200) 2 headers in 78 bytes (1 switches on core 0)
[2023-04-25 18:14:56,920] ERROR in app: Exception on /callback [POST]
Traceback (most recent call last):
  File "/home/eng/.local/lib/python3.8/site-packages/google/cloud/storage/blob.py", line 2540, in upload_from_file
    created_json = self._do_upload(
  File "/home/eng/.local/lib/python3.8/site-packages/google/cloud/storage/blob.py", line 2355, in _do_upload
    response = self._do_multipart_upload(
  File "/home/eng/.local/lib/python3.8/site-packages/google/cloud/storage/blob.py", line 1890, in _do_multipart_upload
    response = upload.transmit(
  File "/home/eng/.local/lib/python3.8/site-packages/google/resumable_media/requests/upload.py", line 153, in transmit
    return _request_helpers.wait_and_retry(
  File "/home/eng/.local/lib/python3.8/site-packages/google/resumable_media/requests/_request_helpers.py", line 148, in wait_and_retry
    response = func()
  File "/home/eng/.local/lib/python3.8/site-packages/google/resumable_media/requests/upload.py", line 149, in retriable_request
    self._process_response(result)
  File "/home/eng/.local/lib/python3.8/site-packages/google/resumable_media/_upload.py", line 114, in _process_response
    _helpers.require_status_code(response, (http.client.OK,), self._get_status_code)
  File "/home/eng/.local/lib/python3.8/site-packages/google/resumable_media/_helpers.py", line 108, in require_status_code
    raise common.InvalidResponse(
google.resumable_media.common.InvalidResponse: ('Request failed with status code', 403, 'Expected one of', <HTTPStatus.OK: 200>)

During handling of the above exception, another exception occurred:

Traceback (most recent call last):
  File "/home/eng/.local/lib/python3.8/site-packages/flask/app.py", line 2528, in wsgi_app
    response = self.full_dispatch_request()
  File "/home/eng/.local/lib/python3.8/site-packages/flask/app.py", line 1825, in full_dispatch_request
    rv = self.handle_user_exception(e)
  File "/home/eng/.local/lib/python3.8/site-packages/flask/app.py", line 1823, in full_dispatch_request
    rv = self.dispatch_request()
  File "/home/eng/.local/lib/python3.8/site-packages/flask/app.py", line 1799, in dispatch_request
    return self.ensure_sync(self.view_functions[rule.endpoint])(**view_args)
  File "/home/eng/teamwork-ai/./app2.py", line 86, in callback
    handler.handle(body, signature)
  File "/home/eng/.local/lib/python3.8/site-packages/linebot/webhook.py", line 263, in handle
    self.__invoke_func(func, event, payload)
  File "/home/eng/.local/lib/python3.8/site-packages/linebot/webhook.py", line 275, in __invoke_func
    func(event)
  File "/home/eng/teamwork-ai/./app2.py", line 111, in reply_text_and_get_user_profile
    blob.upload_from_filename(source_file_name)
  File "/home/eng/.local/lib/python3.8/site-packages/google/cloud/storage/blob.py", line 2684, in upload_from_filename
    self.upload_from_file(
  File "/home/eng/.local/lib/python3.8/site-packages/google/cloud/storage/blob.py", line 2557, in upload_from_file
    _raise_from_invalid_response(exc)
  File "/home/eng/.local/lib/python3.8/site-packages/google/cloud/storage/blob.py", line 4369, in _raise_from_invalid_response
    raise exceptions.from_http_status(response.status_code, message, response=response)
google.api_core.exceptions.Forbidden: 403 POST https://storage.googleapis.com/upload/storage/v1/b/teamwork-cs/o?uploadType=multipart: {
  "error": {
    "code": 403,
    "message": "Access denied.",
    "errors": [
      {
        "message": "Access denied.",
        "domain": "global",
        "reason": "forbidden"
      }
    ]
  }
}
: ('Request failed with status code', 403, 'Expected one of', <HTTPStatus.OK: 200>)
[pid: 52446|app: 0|req: 3/3] 147.92.150.193 () {38 vars in 558 bytes} [Tue Apr 25 18:14:56 2023] POST /callback => generated 265 bytes in 473 msecs (HTTP/1.1 500) 2 headers in 99 bytes (1 switches on core 0)
[pid: 52446|app: 0|req: 4/4] 220.143.17.250 () {60 vars in 1071 bytes} [Tue Apr 25 18:18:26 2023] GET / => generated 207 bytes in 1 msecs (HTTP/1.1 404) 2 headers in 87 bytes (1 switches on core 0)
[pid: 52446|app: 0|req: 5/5] 190.192.250.7 () {32 vars in 355 bytes} [Tue Apr 25 18:36:38 2023] GET / => generated 207 bytes in 1 msecs (HTTP/1.0 404) 2 headers in 87 bytes (1 switches on core 0)
[pid: 52446|app: 0|req: 6/6] 176.40.49.112 () {32 vars in 355 bytes} [Tue Apr 25 19:09:46 2023] GET / => generated 207 bytes in 1 msecs (HTTP/1.0 404) 2 headers in 87 bytes (1 switches on core 0)
[pid: 52446|app: 0|req: 7/7] 220.143.17.250 () {58 vars in 1040 bytes} [Tue Apr 25 19:10:09 2023] GET / => generated 207 bytes in 0 msecs (HTTP/1.1 404) 2 headers in 87 bytes (1 switches on core 0)
[pid: 52446|app: 0|req: 8/8] 147.92.149.169 () {38 vars in 556 bytes} [Tue Apr 25 19:17:52 2023] POST /callback => generated 2 bytes in 1 msecs (HTTP/1.1 200) 2 headers in 78 bytes (1 switches on core 0)
[pid: 52446|app: 0|req: 9/9] 147.92.150.193 () {38 vars in 558 bytes} [Tue Apr 25 19:18:08 2023] POST /callback => generated 2 bytes in 1 msecs (HTTP/1.1 200) 2 headers in 78 bytes (1 switches on core 0)
[2023-04-25 19:18:11,720] ERROR in app: Exception on /callback [POST]
Traceback (most recent call last):
  File "/home/eng/.local/lib/python3.8/site-packages/google/cloud/storage/blob.py", line 2540, in upload_from_file
    created_json = self._do_upload(
  File "/home/eng/.local/lib/python3.8/site-packages/google/cloud/storage/blob.py", line 2355, in _do_upload
    response = self._do_multipart_upload(
  File "/home/eng/.local/lib/python3.8/site-packages/google/cloud/storage/blob.py", line 1890, in _do_multipart_upload
    response = upload.transmit(
  File "/home/eng/.local/lib/python3.8/site-packages/google/resumable_media/requests/upload.py", line 153, in transmit
    return _request_helpers.wait_and_retry(
  File "/home/eng/.local/lib/python3.8/site-packages/google/resumable_media/requests/_request_helpers.py", line 148, in wait_and_retry
    response = func()
  File "/home/eng/.local/lib/python3.8/site-packages/google/resumable_media/requests/upload.py", line 149, in retriable_request
    self._process_response(result)
  File "/home/eng/.local/lib/python3.8/site-packages/google/resumable_media/_upload.py", line 114, in _process_response
    _helpers.require_status_code(response, (http.client.OK,), self._get_status_code)
  File "/home/eng/.local/lib/python3.8/site-packages/google/resumable_media/_helpers.py", line 108, in require_status_code
    raise common.InvalidResponse(
google.resumable_media.common.InvalidResponse: ('Request failed with status code', 403, 'Expected one of', <HTTPStatus.OK: 200>)

During handling of the above exception, another exception occurred:

Traceback (most recent call last):
  File "/home/eng/.local/lib/python3.8/site-packages/flask/app.py", line 2528, in wsgi_app
    response = self.full_dispatch_request()
  File "/home/eng/.local/lib/python3.8/site-packages/flask/app.py", line 1825, in full_dispatch_request
    rv = self.handle_user_exception(e)
  File "/home/eng/.local/lib/python3.8/site-packages/flask/app.py", line 1823, in full_dispatch_request
    rv = self.dispatch_request()
  File "/home/eng/.local/lib/python3.8/site-packages/flask/app.py", line 1799, in dispatch_request
    return self.ensure_sync(self.view_functions[rule.endpoint])(**view_args)
  File "/home/eng/teamwork-ai/./app2.py", line 86, in callback
    handler.handle(body, signature)
  File "/home/eng/.local/lib/python3.8/site-packages/linebot/webhook.py", line 263, in handle
    self.__invoke_func(func, event, payload)
  File "/home/eng/.local/lib/python3.8/site-packages/linebot/webhook.py", line 275, in __invoke_func
    func(event)
  File "/home/eng/teamwork-ai/./app2.py", line 111, in reply_text_and_get_user_profile
    blob.upload_from_filename(source_file_name)
  File "/home/eng/.local/lib/python3.8/site-packages/google/cloud/storage/blob.py", line 2684, in upload_from_filename
    self.upload_from_file(
  File "/home/eng/.local/lib/python3.8/site-packages/google/cloud/storage/blob.py", line 2557, in upload_from_file
    _raise_from_invalid_response(exc)
  File "/home/eng/.local/lib/python3.8/site-packages/google/cloud/storage/blob.py", line 4369, in _raise_from_invalid_response
    raise exceptions.from_http_status(response.status_code, message, response=response)
google.api_core.exceptions.Forbidden: 403 POST https://storage.googleapis.com/upload/storage/v1/b/teamwork-cs/o?uploadType=multipart: {
  "error": {
    "code": 403,
    "message": "Access denied.",
    "errors": [
      {
        "message": "Access denied.",
        "domain": "global",
        "reason": "forbidden"
      }
    ]
  }
}
: ('Request failed with status code', 403, 'Expected one of', <HTTPStatus.OK: 200>)
[pid: 52446|app: 0|req: 10/10] 147.92.150.193 () {38 vars in 558 bytes} [Tue Apr 25 19:18:10 2023] POST /callback => generated 265 bytes in 1321 msecs (HTTP/1.1 500) 2 headers in 99 bytes (1 switches on core 0)
[pid: 52446|app: 0|req: 11/11] 147.92.150.193 () {38 vars in 558 bytes} [Tue Apr 25 19:18:32 2023] POST /callback => generated 2 bytes in 197 msecs (HTTP/1.1 200) 2 headers in 78 bytes (1 switches on core 0)
[pid: 52446|app: 0|req: 12/12] 147.92.150.193 () {38 vars in 558 bytes} [Tue Apr 25 19:18:38 2023] POST /callback => generated 2 bytes in 261 msecs (HTTP/1.1 200) 2 headers in 78 bytes (1 switches on core 0)
[pid: 52446|app: 0|req: 13/13] 147.92.150.193 () {38 vars in 558 bytes} [Tue Apr 25 19:18:50 2023] POST /callback => generated 2 bytes in 157 msecs (HTTP/1.1 200) 2 headers in 78 bytes (1 switches on core 0)
[pid: 52446|app: 0|req: 14/14] 64.62.197.81 () {36 vars in 501 bytes} [Tue Apr 25 19:34:48 2023] GET / => generated 207 bytes in 1 msecs (HTTP/1.1 404) 2 headers in 87 bytes (1 switches on core 0)
[pid: 52446|app: 0|req: 15/15] 200.81.126.200 () {32 vars in 356 bytes} [Tue Apr 25 19:41:00 2023] GET / => generated 207 bytes in 1 msecs (HTTP/1.0 404) 2 headers in 87 bytes (1 switches on core 0)
[pid: 52446|app: 0|req: 16/16] 64.62.197.78 () {36 vars in 632 bytes} [Tue Apr 25 19:41:23 2023] GET /dns-query?name=dnsscan.shadowserver.org&type=A => generated 207 bytes in 1 msecs (HTTP/1.1 404) 2 headers in 87 bytes (1 switches on core 0)
[pid: 52446|app: 0|req: 17/17] 205.210.31.221 () {32 vars in 613 bytes} [Tue Apr 25 19:41:30 2023] GET / => generated 207 bytes in 0 msecs (HTTP/1.1 404) 2 headers in 87 bytes (1 switches on core 0)
[pid: 52446|app: 0|req: 18/18] 64.62.197.83 () {36 vars in 501 bytes} [Tue Apr 25 19:41:50 2023] GET / => generated 207 bytes in 0 msecs (HTTP/1.1 404) 2 headers in 87 bytes (1 switches on core 0)
[pid: 52446|app: 0|req: 19/19] 64.62.197.81 () {36 vars in 513 bytes} [Tue Apr 25 19:43:22 2023] GET /geoserver/web/ => generated 207 bytes in 1 msecs (HTTP/1.1 404) 2 headers in 87 bytes (1 switches on core 0)
[pid: 52446|app: 0|req: 20/20] 64.62.197.87 () {36 vars in 520 bytes} [Tue Apr 25 19:43:35 2023] GET /.git/config => generated 207 bytes in 1 msecs (HTTP/1.1 404) 2 headers in 87 bytes (1 switches on core 0)
[pid: 52446|app: 0|req: 21/21] 147.92.150.194 () {38 vars in 556 bytes} [Tue Apr 25 20:07:53 2023] POST /callback => generated 2 bytes in 7 msecs (HTTP/1.1 200) 2 headers in 78 bytes (1 switches on core 0)
[pid: 52446|app: 0|req: 22/22] 192.227.173.18 () {40 vars in 540 bytes} [Tue Apr 25 20:12:45 2023] POST / => generated 207 bytes in 1 msecs (HTTP/1.1 404) 2 headers in 87 bytes (1 switches on core 0)
[pid: 52446|app: 0|req: 23/23] 147.92.150.193 () {38 vars in 558 bytes} [Tue Apr 25 20:20:31 2023] POST /callback => generated 2 bytes in 574 msecs (HTTP/1.1 200) 2 headers in 78 bytes (1 switches on core 0)
[pid: 52446|app: 0|req: 24/24] 147.92.150.193 () {38 vars in 558 bytes} [Tue Apr 25 20:20:38 2023] POST /callback => generated 2 bytes in 177 msecs (HTTP/1.1 200) 2 headers in 78 bytes (1 switches on core 0)
[pid: 52446|app: 0|req: 25/25] 147.92.150.193 () {38 vars in 558 bytes} [Tue Apr 25 20:20:44 2023] POST /callback => generated 2 bytes in 175 msecs (HTTP/1.1 200) 2 headers in 78 bytes (1 switches on core 0)
[pid: 52446|app: 0|req: 26/26] 147.92.150.193 () {38 vars in 558 bytes} [Tue Apr 25 20:20:48 2023] POST /callback => generated 2 bytes in 162 msecs (HTTP/1.1 200) 2 headers in 78 bytes (1 switches on core 0)
[pid: 52446|app: 0|req: 27/27] 147.92.150.193 () {38 vars in 558 bytes} [Tue Apr 25 20:26:07 2023] POST /callback => generated 2 bytes in 881 msecs (HTTP/1.1 200) 2 headers in 78 bytes (1 switches on core 0)
[pid: 52446|app: 0|req: 28/28] 147.92.150.193 () {38 vars in 558 bytes} [Tue Apr 25 20:26:08 2023] POST /callback => generated 2 bytes in 183 msecs (HTTP/1.1 200) 2 headers in 78 bytes (1 switches on core 0)
[pid: 52446|app: 0|req: 29/29] 147.92.150.193 () {38 vars in 558 bytes} [Tue Apr 25 20:26:08 2023] POST /callback => generated 2 bytes in 133 msecs (HTTP/1.1 200) 2 headers in 78 bytes (1 switches on core 0)
[pid: 52446|app: 0|req: 30/30] 147.92.150.193 () {38 vars in 558 bytes} [Tue Apr 25 20:26:55 2023] POST /callback => generated 2 bytes in 153 msecs (HTTP/1.1 200) 2 headers in 78 bytes (1 switches on core 0)
[pid: 52446|app: 0|req: 31/31] 147.92.150.193 () {38 vars in 558 bytes} [Tue Apr 25 20:27:26 2023] POST /callback => generated 2 bytes in 808 msecs (HTTP/1.1 200) 2 headers in 78 bytes (1 switches on core 0)
[pid: 52446|app: 0|req: 32/32] 205.210.31.50 () {32 vars in 611 bytes} [Tue Apr 25 20:29:27 2023] GET / => generated 207 bytes in 1 msecs (HTTP/1.1 404) 2 headers in 87 bytes (1 switches on core 0)
[pid: 52446|app: 0|req: 33/33] 45.79.181.223 () {36 vars in 498 bytes} [Tue Apr 25 20:36:16 2023] GET / => generated 207 bytes in 1 msecs (HTTP/1.1 404) 2 headers in 87 bytes (1 switches on core 0)
[pid: 52446|app: 0|req: 34/34] 190.16.199.16 () {32 vars in 355 bytes} [Tue Apr 25 21:00:32 2023] GET / => generated 207 bytes in 1 msecs (HTTP/1.0 404) 2 headers in 87 bytes (1 switches on core 0)
[pid: 52446|app: 0|req: 35/35] 147.92.150.193 () {38 vars in 558 bytes} [Tue Apr 25 21:16:55 2023] POST /callback => generated 2 bytes in 1 msecs (HTTP/1.1 200) 2 headers in 78 bytes (1 switches on core 0)
[2023-04-25 21:16:57,839] ERROR in app: Exception on /callback [POST]
Traceback (most recent call last):
  File "/home/eng/.local/lib/python3.8/site-packages/google/cloud/storage/blob.py", line 2540, in upload_from_file
    created_json = self._do_upload(
  File "/home/eng/.local/lib/python3.8/site-packages/google/cloud/storage/blob.py", line 2355, in _do_upload
    response = self._do_multipart_upload(
  File "/home/eng/.local/lib/python3.8/site-packages/google/cloud/storage/blob.py", line 1890, in _do_multipart_upload
    response = upload.transmit(
  File "/home/eng/.local/lib/python3.8/site-packages/google/resumable_media/requests/upload.py", line 153, in transmit
    return _request_helpers.wait_and_retry(
  File "/home/eng/.local/lib/python3.8/site-packages/google/resumable_media/requests/_request_helpers.py", line 148, in wait_and_retry
    response = func()
  File "/home/eng/.local/lib/python3.8/site-packages/google/resumable_media/requests/upload.py", line 149, in retriable_request
    self._process_response(result)
  File "/home/eng/.local/lib/python3.8/site-packages/google/resumable_media/_upload.py", line 114, in _process_response
    _helpers.require_status_code(response, (http.client.OK,), self._get_status_code)
  File "/home/eng/.local/lib/python3.8/site-packages/google/resumable_media/_helpers.py", line 108, in require_status_code
    raise common.InvalidResponse(
google.resumable_media.common.InvalidResponse: ('Request failed with status code', 403, 'Expected one of', <HTTPStatus.OK: 200>)

During handling of the above exception, another exception occurred:

Traceback (most recent call last):
  File "/home/eng/.local/lib/python3.8/site-packages/flask/app.py", line 2528, in wsgi_app
    response = self.full_dispatch_request()
  File "/home/eng/.local/lib/python3.8/site-packages/flask/app.py", line 1825, in full_dispatch_request
    rv = self.handle_user_exception(e)
  File "/home/eng/.local/lib/python3.8/site-packages/flask/app.py", line 1823, in full_dispatch_request
    rv = self.dispatch_request()
  File "/home/eng/.local/lib/python3.8/site-packages/flask/app.py", line 1799, in dispatch_request
    return self.ensure_sync(self.view_functions[rule.endpoint])(**view_args)
  File "/home/eng/teamwork-ai/./app2.py", line 86, in callback
    handler.handle(body, signature)
  File "/home/eng/.local/lib/python3.8/site-packages/linebot/webhook.py", line 263, in handle
    self.__invoke_func(func, event, payload)
  File "/home/eng/.local/lib/python3.8/site-packages/linebot/webhook.py", line 275, in __invoke_func
    func(event)
  File "/home/eng/teamwork-ai/./app2.py", line 111, in reply_text_and_get_user_profile
    blob.upload_from_filename(source_file_name)
  File "/home/eng/.local/lib/python3.8/site-packages/google/cloud/storage/blob.py", line 2684, in upload_from_filename
    self.upload_from_file(
  File "/home/eng/.local/lib/python3.8/site-packages/google/cloud/storage/blob.py", line 2557, in upload_from_file
    _raise_from_invalid_response(exc)
  File "/home/eng/.local/lib/python3.8/site-packages/google/cloud/storage/blob.py", line 4369, in _raise_from_invalid_response
    raise exceptions.from_http_status(response.status_code, message, response=response)
google.api_core.exceptions.Forbidden: 403 POST https://storage.googleapis.com/upload/storage/v1/b/teamwork-cs/o?uploadType=multipart: {
  "error": {
    "code": 403,
    "message": "Access denied.",
    "errors": [
      {
        "message": "Access denied.",
        "domain": "global",
        "reason": "forbidden"
      }
    ]
  }
}
: ('Request failed with status code', 403, 'Expected one of', <HTTPStatus.OK: 200>)
[pid: 52446|app: 0|req: 36/36] 147.92.150.193 () {38 vars in 558 bytes} [Tue Apr 25 21:16:56 2023] POST /callback => generated 265 bytes in 938 msecs (HTTP/1.1 500) 2 headers in 99 bytes (1 switches on core 0)
[pid: 52446|app: 0|req: 37/37] 147.92.150.193 () {38 vars in 558 bytes} [Tue Apr 25 21:17:03 2023] POST /callback => generated 2 bytes in 1 msecs (HTTP/1.1 200) 2 headers in 78 bytes (1 switches on core 0)
[2023-04-25 21:17:05,143] ERROR in app: Exception on /callback [POST]
Traceback (most recent call last):
  File "/home/eng/.local/lib/python3.8/site-packages/google/cloud/storage/blob.py", line 2540, in upload_from_file
    created_json = self._do_upload(
  File "/home/eng/.local/lib/python3.8/site-packages/google/cloud/storage/blob.py", line 2355, in _do_upload
    response = self._do_multipart_upload(
  File "/home/eng/.local/lib/python3.8/site-packages/google/cloud/storage/blob.py", line 1890, in _do_multipart_upload
    response = upload.transmit(
  File "/home/eng/.local/lib/python3.8/site-packages/google/resumable_media/requests/upload.py", line 153, in transmit
    return _request_helpers.wait_and_retry(
  File "/home/eng/.local/lib/python3.8/site-packages/google/resumable_media/requests/_request_helpers.py", line 148, in wait_and_retry
    response = func()
  File "/home/eng/.local/lib/python3.8/site-packages/google/resumable_media/requests/upload.py", line 149, in retriable_request
    self._process_response(result)
  File "/home/eng/.local/lib/python3.8/site-packages/google/resumable_media/_upload.py", line 114, in _process_response
    _helpers.require_status_code(response, (http.client.OK,), self._get_status_code)
  File "/home/eng/.local/lib/python3.8/site-packages/google/resumable_media/_helpers.py", line 108, in require_status_code
    raise common.InvalidResponse(
google.resumable_media.common.InvalidResponse: ('Request failed with status code', 403, 'Expected one of', <HTTPStatus.OK: 200>)

During handling of the above exception, another exception occurred:

Traceback (most recent call last):
  File "/home/eng/.local/lib/python3.8/site-packages/flask/app.py", line 2528, in wsgi_app
    response = self.full_dispatch_request()
  File "/home/eng/.local/lib/python3.8/site-packages/flask/app.py", line 1825, in full_dispatch_request
    rv = self.handle_user_exception(e)
  File "/home/eng/.local/lib/python3.8/site-packages/flask/app.py", line 1823, in full_dispatch_request
    rv = self.dispatch_request()
  File "/home/eng/.local/lib/python3.8/site-packages/flask/app.py", line 1799, in dispatch_request
    return self.ensure_sync(self.view_functions[rule.endpoint])(**view_args)
  File "/home/eng/teamwork-ai/./app2.py", line 86, in callback
    handler.handle(body, signature)
  File "/home/eng/.local/lib/python3.8/site-packages/linebot/webhook.py", line 263, in handle
    self.__invoke_func(func, event, payload)
  File "/home/eng/.local/lib/python3.8/site-packages/linebot/webhook.py", line 275, in __invoke_func
    func(event)
  File "/home/eng/teamwork-ai/./app2.py", line 111, in reply_text_and_get_user_profile
    blob.upload_from_filename(source_file_name)
  File "/home/eng/.local/lib/python3.8/site-packages/google/cloud/storage/blob.py", line 2684, in upload_from_filename
    self.upload_from_file(
  File "/home/eng/.local/lib/python3.8/site-packages/google/cloud/storage/blob.py", line 2557, in upload_from_file
    _raise_from_invalid_response(exc)
  File "/home/eng/.local/lib/python3.8/site-packages/google/cloud/storage/blob.py", line 4369, in _raise_from_invalid_response
    raise exceptions.from_http_status(response.status_code, message, response=response)
google.api_core.exceptions.Forbidden: 403 POST https://storage.googleapis.com/upload/storage/v1/b/teamwork-cs/o?uploadType=multipart: {
  "error": {
    "code": 403,
    "message": "Access denied.",
    "errors": [
      {
        "message": "Access denied.",
        "domain": "global",
        "reason": "forbidden"
      }
    ]
  }
}
: ('Request failed with status code', 403, 'Expected one of', <HTTPStatus.OK: 200>)
[pid: 52446|app: 0|req: 38/38] 147.92.150.193 () {38 vars in 558 bytes} [Tue Apr 25 21:17:04 2023] POST /callback => generated 265 bytes in 145 msecs (HTTP/1.1 500) 2 headers in 99 bytes (1 switches on core 0)
